Workbook

Sheet Treasury Example (No Math)
B1: Date | C1: 1 Mo | D1: 2 Mo | E1: 3 Mo | F1: 4 Mo | G1: 6 Mo | H1: 1 Yr | I1: 2 Yr | J1: 3 Yr | K1: 5 Yr | L1: 7 Yr | M1: 10 Yr | N1: 20 Yr | O1: 30 Yr
B2: 45614 | C2: 4.7 | E2: 4.63 | G2: 4.44 | H2: 4.33 | I2: 4.29 | J2: 4.25 | K2: 4.28 | L2: 4.35 | M2: 4.42 | N2: 4.7 | O2: 4.61
B3: AsOfDate
B4: 45615 | G4: (Note: These zero rates won't exactly match the computations on the next tab due to some simplifying assumptions.)
B6: Period | C6: Year | D6: Name | E6: Rate | G6: Curve | H6: Period | I6: PeriodDate | J6: ZeroRate | K6: ForwardRate
B7: =C7*12 -> 1 | C7: =1/12 -> 0.083333333 | D7: 1MCMT | E7: 4.7 | G7: UST_1M | H7: 0 | I7: 45616 | J7: 4.49983 | K7: 4.4582166
B8: =C8*12 -> 3 | C8: =3/12 -> 0.25 | D8: 3MCMT | E8: 4.63 | G8: UST_1M | H8: 1 | I8: 45646 | J8: 4.49983 | K8: 4.4584923
B9: =C9*12 -> 6 | C9: =6/12 -> 0.5 | D9: 6MCMT | E9: 4.44 | G9: UST_1M | H9: 2 | I9: 45677 | J9: 4.49983 | K9: 4.4584923
B10: =C10*12 -> 12 | C10: 1 | D10: 1YCMT | E10: 4.33 | G10: UST_1M | H10: 3 | I10: 45708 | J10: 4.49983 | K10: 4.3034257
B11: =C11*12 -> 24 | C11: 2 | D11: 2YCMT | E11: 4.29 | G11: UST_1M | H11: 4 | I11: 45736 | J11: 4.4631593 | K11: 4.3044536
B12: =C12*12 -> 36 | C12: 3 | D12: 3YCMT | E12: 4.25 | G12: UST_1M | H12: 5 | I12: 45768 | J12: 4.4377969 | K12: 4.3036826
B13: =C13*12 -> 60 | C13: 5 | D13: 5YCMT | E13: 4.28 | G13: UST_1M | H13: 6 | I13: 45797 | J13: 4.42256 | K13: 4.1447103
B14: =C14*12 -> 84 | C14: 7 | D14: 7YCMT | E14: 4.35 | G14: UST_1M | H14: 7 | I14: 45828 | J14: 4.3871351 | K14: 4.1447103
B15: =C15*12 -> 120 | C15: 10 | D15: 10YCMT | E15: 4.42 | G15: UST_1M | H15: 8 | I15: 45859 | J15: 4.3607526 | K15: 4.144472
B16: =C16*12 -> 240 | C16: 20 | D16: 20YCMT | E16: 4.7 | G16: UST_1M | H16: 9 | I16: 45889 | J16: 4.3409283 | K16: 4.145187
B17: =C17*12 -> 360 | C17: 30 | D17: 30YCMT | E17: 4.61 | G17: UST_1M | H17: 10 | I17: 45922 | J17: 4.3236127 | K17: 4.1439955
G18: UST_1M | H18: 11 | I18: 45950 | J18: 4.3116048 | K18: 4.1447103
G19: UST_1M | H19: 12 | I19: 45981 | J19: 4.30046 | K19: 4.173647
G20: UST_1M | H20: 13 | I20: 46013 | J20: 4.2931359 | K20: 4.1729222
G21: UST_1M | H21: 14 | I21: 46042 | J21: 4.2874491 | K21: 4.1734053
G22: UST_1M | H22: 15 | I22: 46073 | J22: 4.2821683 | K22: 4.1726806
G23: UST_1M | H23: 16 | I23: 46101 | J23: 4.2779789 | K23: 4.1734053
G24: UST_1M | H24: 17 | I24: 46132 | J24: 4.2738711 | K24: 4.1731637
G25: UST_1M | H25: 18 | I25: 46162 | J25: 4.27034 | K25: 4.1669392
G26: UST_1M | H26: 19 | I26: 46195 | J26: 4.2664755 | K26: 4.1657351
G27: UST_1M | H27: 20 | I27: 46223 | J27: 4.263526 | K27: 4.1664575
G28: UST_1M | H28: 21 | I28: 46254 | J28: 4.2605626 | K28: 4.1666983
G29: UST_1M | H29: 22 | I29: 46286 | J29: 4.2577913 | K29: 4.1659759
... G367: UST_1M | H367: 360 | I367: 56573 | J367: 4.55656 | K367: 4.1631451

Sheet Treasury Example (with Math)
J2: Month | K2: Par | L2: Zero | N2: DF | O2: ln(DF) | Q2: Par Rates | R2: =K3 -> 0.0444 | S2: =K9 -> 0.0433 | T2: =K21 -> 0.0429 | U2: =K33 -> 0.0425 | V2: =K57 -> 0.0428
J3: 6 | K3: ='Treasury Example (No Math)'!E9/100 -> 0.0444 | L3: =(1+M3)^12 - 1 -> 0.044877666 | M3: =R18 -> 0.0036650175 | N3: =1/(1+M3)^J3 -> 0.97828924 | O3: =LN(N3) -> -0.021949906
J4: 7 | L4: =(1+M4)^12 - 1 -> 0.044551733 | M4: =(1/N4)^(1/J4) - 1 -> 0.003638924 | N4: =EXP(O4) -> 0.97489429 | O4: =$O$3+$G$25*(J4-$J$3) -> -0.025426234 | R4: Payments | W4: Discounted
J5: 8 | L5: =(1+M5)^12 - 1 -> 0.04430735 | M5: =(1/N5)^(1/J5) - 1 -> 0.0036193543 | N5: =EXP(O5) -> 0.97151112 | O5: =$O$3+$G$25*(J5-$J$3) -> -0.028902562 | R5: 6-Mo | S5: 1-Yr | T5: 2-Yr | U5: 3-Yr | V5: 5-Yr | W5: 1-Yr | X5: 1-Yr | Y5: 2-Yr | Z5: 3-Yr | AA5: 5-Yr | AC5: Find where the row with "12" is in the Month column;
J6: 9 | L6: =(1+M6)^12 - 1 -> 0.044117314 | M6: =(1/N6)^(1/J6) - 1 -> 0.0036041337 | N6: =EXP(O6) -> 0.96813969 | O6: =$O$3+$G$25*(J6-$J$3) -> -0.032378889 | Q6: 6 | R6: =R2/2+1 -> 1.0222 | S6: =S2/2 -> 0.02165 | T6: =T2/2 -> 0.02145 | U6: =U2/2 -> 0.02125 | V6: =V2/2 -> 0.0214 | W6: =R6/(1+INDEX($M$3:$M$57, MATCH($Q6,$J$3:$J$57,0)))^$Q6 -> 1.0000073 | X6: =S6/(1+INDEX($M$3:$M$57, MATCH($Q6,$J$3:$J$57,0)))^$Q6 -> 0.021179962 | Y6: =T6/(1+INDEX($M$3:$M$57, MATCH($Q6,$J$3:$J$57,0)))^$Q6 -> 0.020984304 | Z6: =U6/(1+INDEX($M$3:$M$57, MATCH($Q6,$J$3:$J$57,0)))^$Q6 -> 0.020788646 | AA6: =V6/(1+INDEX($M$3:$M$57, MATCH($Q6,$J$3:$J$57,0)))^$Q6 -> 0.02093539 | AC6: Get the value from that row that's in column M, call it x
J7: 10 | L7: =(1+M7)^12 - 1 -> 0.04396531 | M7: =(1/N7)^(1/J7) - 1 -> 0.0035919574 | N7: =EXP(O7) -> 0.96477997 | O7: =$O$3+$G$25*(J7-$J$3) -> -0.035855217 | Q7: =Q6+6 -> 12 | S7: =S2/2+1 -> 1.02165 | T7: =T2/2 -> 0.02145 | U7: =U2/2 -> 0.02125 | V7: =V2/2 -> 0.0214 | X7: =S7/(1+INDEX($M$3:$M$57, MATCH($Q7,$J$3:$J$57,0)))^$Q7 -> 0.97883822 | Y7: =T7/(1+INDEX($M$3:$M$57, MATCH($Q7,$J$3:$J$57,0)))^$Q7 -> 0.020551147 | Z7: =U7/(1+INDEX($M$3:$M$57, MATCH($Q7,$J$3:$J$57,0)))^$Q7 -> 0.020359528 | AA7: =V7/(1+INDEX($M$3:$M$57, MATCH($Q7,$J$3:$J$57,0)))^$Q7 -> 0.020503243 | AC7: The discount (1+x)^(-12)
J8: 11 | L8: =(1+M8)^12 - 1 -> 0.043840959 | M8: =(1/N8)^(1/J8) - 1 -> 0.0035819951 | N8: =EXP(O8) -> 0.9614319 | O8: =$O$3+$G$25*(J8-$J$3) -> -0.039331545 | Q8: =Q7+6 -> 18 | T8: =T2/2 -> 0.02145 | U8: =U2/2 -> 0.02125 | V8: =V2/2 -> 0.0214 | Y8: =T8/(1+INDEX($M$3:$M$57, MATCH($Q8,$J$3:$J$57,0)))^$Q8 -> 0.020124108 | Z8: =U8/(1+INDEX($M$3:$M$57, MATCH($Q8,$J$3:$J$57,0)))^$Q8 -> 0.01993647 | AA8: =V8/(1+INDEX($M$3:$M$57, MATCH($Q8,$J$3:$J$57,0)))^$Q8 -> 0.020077198
J9: 12 | K9: ='Treasury Example (No Math)'!E10/100 -> 0.0433 | L9: =(1+M9)^12 - 1 -> 0.043737345 | M9: =S18 -> 0.0035736932 | N9: =1/(1+M9)^J9 -> 0.95809545 | O9: =LN(N9) -> -0.042807873 | Q9: =Q8+6 -> 24 | T9: =T2/2+1 -> 1.02145 | U9: =U2/2 -> 0.02125 | V9: =V2/2 -> 0.0214 | Y9: =T9/(1+INDEX($M$3:$M$57, MATCH($Q9,$J$3:$J$57,0)))^$Q9 -> 0.93839787 | Z9: =U9/(1+INDEX($M$3:$M$57, MATCH($Q9,$J$3:$J$57,0)))^$Q9 -> 0.019522203 | AA9: =V9/(1+INDEX($M$3:$M$57, MATCH($Q9,$J$3:$J$57,0)))^$Q9 -> 0.019660007
J10: =J9+1 -> 13 | L10: =(1+M10)^12 - 1 -> 0.04367221 | M10: =(1/N10)^(1/J10) - 1 -> 0.0035684739 | N10: =EXP(O10) -> 0.95474825 | O10: =$O$9+$G$26*(J10-$J$9) -> -0.046307587 | Q10: =Q9+6 -> 30 | U10: =U2/2 -> 0.02125 | V10: =V2/2 -> 0.0214 | Z10: =U10/(1+INDEX($M$3:$M$57, MATCH($Q10,$J$3:$J$57,0)))^$Q10 -> 0.019124432 | AA10: =V10/(1+INDEX($M$3:$M$57, MATCH($Q10,$J$3:$J$57,0)))^$Q10 -> 0.019259428 | AJ10: INDEX($M$3:$M$57, MATCH($Q7,$J$3:$J$57,0))
J11: =J10+1 -> 14 | L11: =(1+M11)^12 - 1 -> 0.043616382 | M11: =(1/N11)^(1/J11) - 1 -> 0.0035640003 | N11: =EXP(O11) -> 0.95141274 | O11: =$O$9+$G$26*(J11-$J$9) -> -0.049807301 | Q11: =Q10+6 -> 36 | U11: =U2/2+1 -> 1.02125 | V11: =V2/2 -> 0.0214 | Z11: =U11/(1+INDEX($M$3:$M$57, MATCH($Q11,$J$3:$J$57,0)))^$Q11 -> 0.90037074 | AA11: =V11/(1+INDEX($M$3:$M$57, MATCH($Q11,$J$3:$J$57,0)))^$Q11 -> 0.01886701 | AJ11: Return value in (matched location)
J12: =J11+1 -> 15 | L12: =(1+M12)^12 - 1 -> 0.043568001 | M12: =(1/N12)^(1/J12) - 1 -> 0.0035601232 | N12: =EXP(O12) -> 0.94808889 | O12: =$O$9+$G$26*(J12-$J$9) -> -0.053307015 | Q12: =Q11+6 -> 42 | V12: =V2/2 -> 0.0214 | AA12: =V12/(1+INDEX($M$3:$M$57, MATCH($Q12,$J$3:$J$57,0)))^$Q12 -> 0.018468268
J13: =J12+1 -> 16 | L13: =(1+M13)^12 - 1 -> 0.04352567 | M13: =(1/N13)^(1/J13) - 1 -> 0.0035567308 | N13: =EXP(O13) -> 0.94477665 | O13: =$O$9+$G$26*(J13-$J$9) -> -0.056806729 | Q13: =Q12+6 -> 48 | V13: =V2/2 -> 0.0214 | AA13: =V13/(1+INDEX($M$3:$M$57, MATCH($Q13,$J$3:$J$57,0)))^$Q13 -> 0.018077954
J14: =J13+1 -> 17 | L14: =(1+M14)^12 - 1 -> 0.04348832 | M14: =(1/N14)^(1/J14) - 1 -> 0.0035537374 | N14: =EXP(O14) -> 0.94147598 | O14: =$O$9+$G$26*(J14-$J$9) -> -0.060306443 | Q14: =Q13+6 -> 54 | V14: =V2/2 -> 0.0214 | AA14: =V14/(1+INDEX($M$3:$M$57, MATCH($Q14,$J$3:$J$57,0)))^$Q14 -> 0.017695888
J15: =J14+1 -> 18 | L15: =(1+M15)^12 - 1 -> 0.043455121 | M15: =(1/N15)^(1/J15) - 1 -> 0.0035510767 | N15: =EXP(O15) -> 0.93818684 | O15: =$O$9+$G$26*(J15-$J$9) -> -0.063806157 | Q15: =Q14+6 -> 60 | V15: =V2/2+1 -> 1.0214 | AA15: =V15/(1+INDEX($M$3:$M$57, MATCH($Q15,$J$3:$J$57,0)))^$Q15 -> 0.82675635
J16: =J15+1 -> 19 | L16: =(1+M16)^12 - 1 -> 0.043425417 | M16: =(1/N16)^(1/J16) - 1 -> 0.003548696 | N16: =EXP(O16) -> 0.9349092 | O16: =$O$9+$G$26*(J16-$J$9) -> -0.067305871
J17: =J16+1 -> 20 | L17: =(1+M17)^12 - 1 -> 0.043398685 | M17: =(1/N17)^(1/J17) - 1 -> 0.0035465535 | N17: =EXP(O17) -> 0.931643 | O17: =$O$9+$G$26*(J17-$J$9) -> -0.070805585 | R17: r_6 | S17: r_12 | T17: r_24 | U17: r_36 | V17: r_60
B18: Month | C18: Par | D18: Zero | F18: DF | G18: ln(DF) | J18: =J17+1 -> 21 | L18: =(1+M18)^12 - 1 -> 0.043374499 | M18: =(1/N18)^(1/J18) - 1 -> 0.0035446149 | N18: =EXP(O18) -> 0.92838821 | O18: =$O$9+$G$26*(J18-$J$9) -> -0.074305299 | Q18: Zero Rates | R18: 0.0036650175 | S18: 0.0035736932 | T18: 0.0035397686 | U18: 0.0035054641 | V18: 0.0035298734 | W18: =SUM(W6:W7)-1 -> 7.2611497e-06 | X18: =SUM(X6:X9)-1 -> 1.8177329e-05 | Y18: =SUM(Y6:Y9)-1 -> 5.7425725e-05 | Z18: =SUM(Z6:Z11)-1 -> 0.00010201941 | AA18: =SUM(AA6:AA15)-1 -> 0.00030073829
B19: 6 | C19: =R2 -> 0.0444 | D19: =(1+E19)^12 - 1 -> 0.044877666 | E19: =R18 -> 0.0036650175 | F19: =1/(1+E19)^B19 -> 0.97828924 | G19: =LN(F19) -> -0.021949906 | J19: =J18+1 -> 22 | L19: =(1+M19)^12 - 1 -> 0.043352513 | M19: =(1/N19)^(1/J19) - 1 -> 0.0035428526 | N19: =EXP(O19) -> 0.9251448 | O19: =$O$9+$G$26*(J19-$J$9) -> -0.077805014 | W19: (Note: You have to use "Goal Seek" or some solver to get these all to be zeroes.)
B20: 12 | C20: =S2 -> 0.0433 | D20: =(1+E20)^12 - 1 -> 0.043737345 | E20: =S18 -> 0.0035736932 | F20: =1/(1+E20)^B20 -> 0.95809545 | G20: =LN(F20) -> -0.042807873 | J20: =J19+1 -> 23 | L20: =(1+M20)^12 - 1 -> 0.043332438 | M20: =(1/N20)^(1/J20) - 1 -> 0.0035412436 | N20: =EXP(O20) -> 0.92191272 | O20: =$O$9+$G$26*(J20-$J$9) -> -0.081304728
B21: 24 | C21: =T2 -> 0.0429 | D21: =(1+E21)^12 - 1 -> 0.043314037 | E21: =T18 -> 0.0035397686 | F21: =1/(1+E21)^B21 -> 0.91869192 | G21: =LN(F21) -> -0.084804442 | J21: =J20+1 -> 24 | K21: ='Treasury Example (No Math)'!E11/100 -> 0.0429 | L21: =(1+M21)^12 - 1 -> 0.043314037 | M21: =T18 -> 0.0035397686 | N21: =1/(1+M21)^J21 -> 0.91869192 | O21: =LN(N21) -> -0.084804442
B22: 36 | C22: =U2 -> 0.0425 | D22: =(1+E22)^12 - 1 -> 0.042886148 | E22: =U18 -> 0.0035054641 | F22: =1/(1+E22)^B22 -> 0.88163597 | G22: =LN(F22) -> -0.12597603 | J22: =J21+1 -> 25 | L22: =(1+M22)^12 - 1 -> 0.043262681 | M22: =(1/N22)^(1/J22) - 1 -> 0.003535652 | N22: =EXP(O22) -> 0.91554532 | O22: =$O$21+$G$27*(J22-$J$21) -> -0.088235408 | R22: Date | S22: 1 Mo | T22: 2 Mo | U22: 3 Mo | V22: 4 Mo | W22: 6 Mo
B23: 60 | C23: =V2 -> 0.0428 | D23: =(1+E23)^12 - 1 -> 0.043190594 | E23: =V18 -> 0.0035298734 | F23: =1/(1+E23)^B23 -> 0.80943446 | G23: =LN(F23) -> -0.21141948 | J23: =J22+1 -> 26 | L23: =(1+M23)^12 - 1 -> 0.043215278 | M23: =(1/N23)^(1/J23) - 1 -> 0.0035318521 | N23: =EXP(O23) -> 0.9124095 | O23: =$O$21+$G$27*(J23-$J$21) -> -0.091666374 | R23: 45615 | S23: 4.67 | T23: 4.63 | U23: 4.62 | V23: 4.51 | W23: 4.44
J24: =J23+1 -> 27 | L24: =(1+M24)^12 - 1 -> 0.043171388 | M24: =(1/N24)^(1/J24) - 1 -> 0.0035283337 | N24: =EXP(O24) -> 0.90928442 | O24: =$O$21+$G$27*(J24-$J$21) -> -0.09509734 | S24: 1 Yr | T24: 2 Yr | U24: 3 Yr | V24: 5 Yr | W24: 7 Yr | X24: 10 Yr | Y24: 20 Yr | Z24: 30 Yr
E25: Slope 6-12 | G25: =(G20-G19)/(B20-B19) -> -0.0034763277 | J25: =J24+1 -> 28 | L25: =(1+M25)^12 - 1 -> 0.043130634 | M25: =(1/N25)^(1/J25) - 1 -> 0.0035250666 | N25: =EXP(O25) -> 0.90617004 | O25: =$O$21+$G$27*(J25-$J$21) -> -0.098528306 | S25: 4.34 | T25: 4.27 | U25: 4.24 | V25: 4.25 | W25: 4.32 | X25: 4.39 | Y25: 4.66 | Z25: 4.57
E26: Slope 12-24 | G26: =(G21-G20)/(B21-B20) -> -0.0034997141 | J26: =J25+1 -> 29 | L26: =(1+M26)^12 - 1 -> 0.043092693 | M26: =(1/N26)^(1/J26) - 1 -> 0.0035220248 | N26: =EXP(O26) -> 0.90306633 | O26: =$O$21+$G$27*(J26-$J$21) -> -0.10195927
E27: Slope 24-36 | G27: =(G22-G21)/(B22-B21) -> -0.0034309661 | J27: =J26+1 -> 30 | L27: =(1+M27)^12 - 1 -> 0.043057282 | M27: =(1/N27)^(1/J27) - 1 -> 0.0035191858 | N27: =EXP(O27) -> 0.89997325 | O27: =$O$21+$G$27*(J27-$J$21) -> -0.10539024
E28: Slope 36-60 | G28: =(G23-G22)/(B23-B22) -> -0.0035601435 | J28: =J27+1 -> 31 | L28: =(1+M28)^12 - 1 -> 0.043024157 | M28: =(1/N28)^(1/J28) - 1 -> 0.00351653 | N28: =EXP(O28) -> 0.89689076 | O28: =$O$21+$G$27*(J28-$J$21) -> -0.1088212
J29: =J28+1 -> 32 | L29: =(1+M29)^12 - 1 -> 0.042993104 | M29: =(1/N29)^(1/J29) - 1 -> 0.0035140401 | N29: =EXP(O29) -> 0.89381883 | O29: =$O$21+$G$27*(J29-$J$21) -> -0.11225217
J30: =J29+1 -> 33 | L30: =(1+M30)^12 - 1 -> 0.042963933 | M30: =(1/N30)^(1/J30) - 1 -> 0.0035117012 | N30: =EXP(O30) -> 0.89075743 | O30: =$O$21+$G$27*(J30-$J$21) -> -0.11568314
J31: =J30+1 -> 34 | L31: =(1+M31)^12 - 1 -> 0.042936479 | M31: =(1/N31)^(1/J31) - 1 -> 0.0035094999 | N31: =EXP(O31) -> 0.88770651 | O31: =$O$21+$G$27*(J31-$J$21) -> -0.1191141
J32: =J31+1 -> 35 | L32: =(1+M32)^12 - 1 -> 0.042910594 | M32: =(1/N32)^(1/J32) - 1 -> 0.0035074244 | N32: =EXP(O32) -> 0.88466603 | O32: =$O$21+$G$27*(J32-$J$21) -> -0.12254507
J33: =J32+1 -> 36 | K33: ='Treasury Example (No Math)'!E12/100 -> 0.0425 | L33: =(1+M33)^12 - 1 -> 0.042886148 | M33: =U18 -> 0.0035054641 | N33: =1/(1+M33)^J33 -> 0.88163597 | O33: =LN(N33) -> -0.12597603
J34: =J33+1 -> 37 | L34: =(1+M34)^12 - 1 -> 0.042906716 | M34: =(1/N34)^(1/J34) - 1 -> 0.0035071134 | N34: =EXP(O34) -> 0.8785028 | O34: =$O$33+$G$28*(J34-$J$33) -> -0.12953618
J35: =J34+1 -> 38 | L35: =(1+M35)^12 - 1 -> 0.042926201 | M35: =(1/N35)^(1/J35) - 1 -> 0.0035086758 | N35: =EXP(O35) -> 0.87538077 | O35: =$O$33+$G$28*(J35-$J$33) -> -0.13309632
J36: =J35+1 -> 39 | L36: =(1+M36)^12 - 1 -> 0.042944688 | M36: =(1/N36)^(1/J36) - 1 -> 0.0035101582 | N36: =EXP(O36) -> 0.87226983 | O36: =$O$33+$G$28*(J36-$J$33) -> -0.13665647
J37: =J36+1 -> 40 | L37: =(1+M37)^12 - 1 -> 0.042962251 | M37: =(1/N37)^(1/J37) - 1 -> 0.0035115664 | N37: =EXP(O37) -> 0.86916995 | O37: =$O$33+$G$28*(J37-$J$33) -> -0.14021661
J38: =J37+1 -> 41 | L38: =(1+M38)^12 - 1 -> 0.042978957 | M38: =(1/N38)^(1/J38) - 1 -> 0.0035129059 | N38: =EXP(O38) -> 0.86608108 | O38: =$O$33+$G$28*(J38-$J$33) -> -0.14377675
J39: =J38+1 -> 42 | L39: =(1+M39)^12 - 1 -> 0.042994868 | M39: =(1/N39)^(1/J39) - 1 -> 0.0035141816 | N39: =EXP(O39) -> 0.86300319 | O39: =$O$33+$G$28*(J39-$J$33) -> -0.1473369
J40: =J39+1 -> 43 | L40: =(1+M40)^12 - 1 -> 0.04301004 | M40: =(1/N40)^(1/J40) - 1 -> 0.003515398 | N40: =EXP(O40) -> 0.85993623 | O40: =$O$33+$G$28*(J40-$J$33) -> -0.15089704
J41: =J40+1 -> 44 | L41: =(1+M41)^12 - 1 -> 0.043024521 | M41: =(1/N41)^(1/J41) - 1 -> 0.0035165592 | N41: =EXP(O41) -> 0.85688018 | O41: =$O$33+$G$28*(J41-$J$33) -> -0.15445718
...

Sheet Match Index
A1: Data | B1: Data
A2: Apples | B2: Lemons
A3: Bananas | B3: Pears
E4: Formula | F4: Description | G4: Result
E5: =INDEX(A2:B3,2,2) -> Pears | F5: Value at the intersection of the second row and second column in the range A2:B3. | G5: Pears
E6: =INDEX(A2:B3,2,1) -> Bananas | F6: Value at the intersection of the second row and first column in the range A2:B3. | G6: Bananas
D9: =MATCH("Lemons",A2:B3,1) -> #N/A
D10: =MATCH("Bananas",A2:A3) -> 2
D11: =MATCH("Pears",A2:B3) -> #N/A

Sheet Sheet1
A1: Data | B1: Description
A2: 39493 | B2: Settlement date
A3: 42689 | B3: Maturity date | C3: =_xlfn.DAYS("15-NOV-2016", "15-FEB-2008") -> 3196 | E3: 39493 | F3: {=D} -> #NAME?
A4: 0.0575 | B4: Percent coupon | E4: =DATEVALUE(A3) -> #VALUE!
A5: 95.04287 | B5: Price
A6: 100 | B6: Redemption value
A7: 2 | B7: Frequency is semiannual (see above)
A8: 0 | B8: 30/360 basis (see above)
A9: Formula | B9: Description (Result) | C9: Result
A10: =YIELD(A2,A3,A4,A5,A6,A7,A8) -> #VALUE! | B10: The yield, for the bond with the terms above (0.065 or 6.5%) | C10: 0.065

Sheet Python sample
A1: Iris data set (as Excel table)
A2: sepal_length | B2: sepal_width | C2: petal_length | D2: petal_width | E2: species | G2: Select cell G3 to see the sample Python formula.
A3: 5.1 | B3: 3.5 | C3: 1.4 | D3: 0.2 | E3: setosa | G3: {=_xlfn._xlws.PY(0,1,IrisDataSet2[#All])} -> #VALUE!
A4: 4.9 | B4: 3 | C4: 1.4 | D4: 0.2 | E4: setosa
A5: 4.7 | B5: 3.2 | C5: 1.3 | D5: 0.2 | E5: setosa | G5: Select cell G6 to see the sample Python formula.
A6: 4.6 | B6: 3.1 | C6: 1.5 | D6: 0.2 | E6: setosa | G6: {=_xlfn._xlws.PY(1,0)} | H6: sepal_length | I6: sepal_width | J6: petal_length | K6: petal_width
A7: 5 | B7: 3.6 | C7: 1.4 | D7: 0.2 | E7: setosa | G7: count | H7: 150 | I7: 150 | J7: 150 | K7: 150
A8: 5.4 | B8: 3.9 | C8: 1.7 | D8: 0.4 | E8: setosa | G8: mean | H8: 5.8433333 | I8: 3.054 | J8: 3.7586667 | K8: 1.1986667
A9: 4.6 | B9: 3.4 | C9: 1.4 | D9: 0.3 | E9: setosa | G9: std | H9: 0.82806613 | I9: 0.43359431 | J9: 1.7644204 | K9: 0.76316074
A10: 5 | B10: 3.4 | C10: 1.5 | D10: 0.2 | E10: setosa | G10: min | H10: 4.3 | I10: 2 | J10: 1 | K10: 0.1
A11: 4.4 | B11: 2.9 | C11: 1.4 | D11: 0.2 | E11: setosa | G11: 25% | H11: 5.1 | I11: 2.8 | J11: 1.6 | K11: 0.3
A12: 4.9 | B12: 3.1 | C12: 1.5 | D12: 0.1 | E12: setosa | G12: 50% | H12: 5.8 | I12: 3 | J12: 4.35 | K12: 1.3
A13: 5.4 | B13: 3.7 | C13: 1.5 | D13: 0.2 | E13: setosa | G13: 75% | H13: 6.4 | I13: 3.3 | J13: 5.1 | K13: 1.8
A14: 4.8 | B14: 3.4 | C14: 1.6 | D14: 0.2 | E14: setosa | G14: max | H14: 7.9 | I14: 4.4 | J14: 6.9 | K14: 2.5
A15: 4.8 | B15: 3 | C15: 1.4 | D15: 0.1 | E15: setosa
A16: 4.3 | B16: 3 | C16: 1.1 | D16: 0.1 | E16: setosa
A17: 5.8 | B17: 4 | C17: 1.2 | D17: 0.2 | E17: setosa
A18: 5.7 | B18: 4.4 | C18: 1.5 | D18: 0.4 | E18: setosa
A19: 5.4 | B19: 3.9 | C19: 1.3 | D19: 0.4 | E19: setosa
A20: 5.1 | B20: 3.5 | C20: 1.4 | D20: 0.3 | E20: setosa
A21: 5.7 | B21: 3.8 | C21: 1.7 | D21: 0.3 | E21: setosa
A22: 5.1 | B22: 3.8 | C22: 1.5 | D22: 0.3 | E22: setosa
A23: 5.4 | B23: 3.4 | C23: 1.7 | D23: 0.2 | E23: setosa
A24: 5.1 | B24: 3.7 | C24: 1.5 | D24: 0.4 | E24: setosa
A25: 4.6 | B25: 3.6 | C25: 1 | D25: 0.2 | E25: setosa
A26: 5.1 | B26: 3.3 | C26: 1.7 | D26: 0.5 | E26: setosa
... A152: 5.9 | B152: 3 | C152: 5.1 | D152: 1.8 | E152: virginica
A154: Data attribution: Fisher,R. A.. (1988). Iris. UCI Machine Learning Repository. https://doi.org/10.24432/C56C76
